2015-09-09 15:19:08,680 - run - INFO - 开始爬取oi.
2015-09-09 15:19:17,289 - run - INFO - 开始爬取oi.
2015-09-09 15:19:25,869 - run - INFO - 开始爬取oi.
2015-09-10 13:15:21,111 - run - INFO - 开始爬取'http://cn.python-requests.org/zh_CN/latest/user/quickstart.html'.
2015-09-10 13:15:39,055 - run - ERROR - [EXCEPTION]Traceback as below:
E:\PythonProjectLF\simple_crawler_for_interview\lib\fetcher.py line 23 in start()
  => 'r = s.get(self.url,self.headers)'
  ** <type 'exceptions.TypeError'>: get() takes exactly 2 arguments (3 given)
2015-09-10 13:15:39,055 - run - INFO - 开始爬取'http://cn.python-requests.org/zh_CN/latest/user/quickstart.html'.
2015-09-10 13:16:54,631 - run - ERROR - [EXCEPTION]Traceback as below:
E:\PythonProjectLF\simple_crawler_for_interview\lib\fetcher.py line 23 in start()
  => 'r = s.get(self.url,headers = self.headers)'
  ** <type 'exceptions.AttributeError'>: 'str' object has no attribute 'items'
C:\Python27\lib\site-packages\requests\sessions.py line 477 in get()
  => "return self.request('GET', url, **kwargs)"
  ** <type 'exceptions.AttributeError'>: 'str' object has no attribute 'items'
C:\Python27\lib\site-packages\requests\sessions.py line 451 in request()
  => 'prep = self.prepare_request(req)'
  ** <type 'exceptions.AttributeError'>: 'str' object has no attribute 'items'
C:\Python27\lib\site-packages\requests\sessions.py line 382 in prepare_request()
  => 'hooks=merge_hooks(request.hooks, self.hooks),'
  ** <type 'exceptions.AttributeError'>: 'str' object has no attribute 'items'
C:\Python27\lib\site-packages\requests\models.py line 305 in prepare()
  => 'self.prepare_headers(headers)'
  ** <type 'exceptions.AttributeError'>: 'str' object has no attribute 'items'
C:\Python27\lib\site-packages\requests\models.py line 411 in prepare_headers()
  => 'self.headers = CaseInsensitiveDict((to_native_string(name), value) for name, value in headers.items())'
  ** <type 'exceptions.AttributeError'>: 'str' object has no attribute 'items'
2015-09-10 13:16:54,631 - run - INFO - 开始爬取'http://cn.python-requests.org/zh_CN/latest/user/quickstart.html'.
2015-09-10 13:19:42,348 - run - ERROR - [EXCEPTION]Traceback as below:
E:\PythonProjectLF\simple_crawler_for_interview\lib\fetcher.py line 23 in start()
  => 'r = s.get(self.url,headers = self.headers)'
  ** <class 'requests.exceptions.InvalidSchema'>: No connection adapters were found for ''http://cn.python-requests.org/zh_CN/latest/user/quickstart.html''
C:\Python27\lib\site-packages\requests\sessions.py line 477 in get()
  => "return self.request('GET', url, **kwargs)"
  ** <class 'requests.exceptions.InvalidSchema'>: No connection adapters were found for ''http://cn.python-requests.org/zh_CN/latest/user/quickstart.html''
C:\Python27\lib\site-packages\requests\sessions.py line 465 in request()
  => 'resp = self.send(prep, **send_kwargs)'
  ** <class 'requests.exceptions.InvalidSchema'>: No connection adapters were found for ''http://cn.python-requests.org/zh_CN/latest/user/quickstart.html''
C:\Python27\lib\site-packages\requests\sessions.py line 567 in send()
  => 'adapter = self.get_adapter(url=request.url)'
  ** <class 'requests.exceptions.InvalidSchema'>: No connection adapters were found for ''http://cn.python-requests.org/zh_CN/latest/user/quickstart.html''
C:\Python27\lib\site-packages\requests\sessions.py line 641 in get_adapter()
  => 'raise InvalidSchema("No connection adapters were found for \'%s\'" % url)'
  ** <class 'requests.exceptions.InvalidSchema'>: No connection adapters were found for ''http://cn.python-requests.org/zh_CN/latest/user/quickstart.html''
2015-09-10 13:19:42,348 - run - INFO - 开始爬取'http://cn.python-requests.org/zh_CN/latest/user/quickstart.html'.
